Workbook

Sheet Huvudbok
A1: Lunds Naturskyddsförening – Huvudbok 2026-10-21 (rader från Huvudbok_261021.docx)
A2: Rader överförda i huvudbokens ordning. Röda kommentarer markerar avvikelser. Verifikat 38–40 och Kvisten-raden är nya sedan förra perioden (2026-09-23).
A4: Kategori | B4: Ver | C4: Datum | D4: Text | E4: Belopp (kr) | F4: Kommentar
A5: Medlemsavgifter | C5: 2026-07-01 | D5: Medlemsavgifter | E5: 66156 | F5: Saknar verifikationsnummer
A6: Miljöanslag | B6: 2 | C6: 2026-01-02 | D6: Fotoutställning (miljöanslag) | E6: 54000
A7: Ersättning cykelkarta | B7: 22 | C7: 2026-05-10 | D7: Cykelkarta Sjöbo kommun | E7: 13000
A8: Ersättning cykelkarta | B8: 23 | C8: 2026-06-10 | D8: Cykelkarta Lunds kommun | E8: 45000
A9: Ersättning cykelkarta | B9: 36 | C9: 2026-09-18 | D9: Cykelkarta Helsingborgs kommun | E9: 39000
A10: Administration | B10: 1 | C10: 2026-01-02 | D10: Avgift Ekobanken | E10: -1490
A11: Administration | B11: 16 | C11: 2026-04-13 | D11: Storkfadder | E11: -1000
A12: Administration | B12: 31 | C12: 2026-08-20 | D12: Trycksaker inför valet | E12: -3875
A13: Administration | B13: 24 | C13: 2026-06-01 | D13: Försäljning bok "Cykelturer i Lundabygden" | E13: 2000 | F13: Intäkt, står bland Administrationens rader i huvudboken
A14: Administration | B14: 39 | C14: 2026-09-30 | D14: Utlägg Skördefesten muggar | E14: -100 | F14: Skrivet -100.00 (punkt) i huvudboken
A15: Administration | C15: 2026-11-05 | D15: Hyra Kvisten Skrylle 16/8 | E15: -1450 | F15: Saknar verifikationsnummer; datum 2026-11-05 men text "16/8"
A16: Programblad | B16: 5 | C16: 2026-02-02 | D16: Tryck vårprogram | E16: -16430
A17: Programblad | B17: 6 | C17: 2026-02-16 | D17: Distribution vårprogram | E17: -20494
A18: Programblad | B18: 12 | C18: 2026-03-20 | D18: Frimärke | E18: -220
A19: Programblad | B19: 13 | C19: 2026-03-20 | D19: Etiketter | E19: -498
A20: Programblad | B20: 30 | C20: 2026-08-17 | D20: Etiketter höstprogram | E20: -289
A21: Programblad | B21: 35 | C21: 2026-09-18 | D21: Tryck höstprogram | E21: -16833
A22: Programblad | B22: 37 | C22: 2026-09-21 | D22: Distribution höstprogram | E22: -20494
A23: Programblad | B23: 38 | C23: 2026-09-28 | D23: Frimärken | E23: -242
A24: Arrangemang | B24: 14 | C24: 2026-03-20 | D24: Fika årsmötet | E24: -218.85
A25: Arrangemang | B25: 26 | C25: 2026-06-25 | D25: Polistillstånd inför valet | E25: -990
A26: Cykelkarta | B26: 4 | C26: 2026-02-02 | D26: Månadshyra server cykelkarta | E26: -330.75
A27: Cykelkarta | B27: 8 | C27: 2026-03-04 | D27: Månadshyra server cykelkarta | E27: -333 | F27: Skrivet -333.00 (punkt) i huvudboken
A28: Cykelkarta | B28: 15 | C28: 2026-04-02 | D28: Månadshyra server cykelkarta | E28: -339.16
A29: Cykelkarta | B29: 18 | C29: 2026-05-05 | D29: Månadshyra server cykelkarta | E29: -338
A30: Cykelkarta | B30: 19 | C30: 2026-05-28 | D30: Tryck cykelkarta Lund tätort | E30: -20331
A31: Cykelkarta | B31: 20 | C31: 2026-05-25 | D31: Tryck cykelkarta Lunds omgivningar | E31: -20331
A32: Cykelkarta | B32: 21 | C32: 2026-06-01 | D32: Månadshyra server cykelkarta maj | E32: -440
A33: Cykelkarta | B33: 25 | C33: 2026-06-22 | D33: Tryck cykelkarta Sjöbo kommun | E33: -12031
A34: Cykelkarta | B34: 27 | C34: 2026-07-01 | D34: Månadshyra server cykelkarta juni | E34: -451
A35: Cykelkarta | B35: 28 | C35: 2026-08-04 | D35: Månadshyra server cykelkarta juli | E35: -451
A36: Cykelkarta | B36: 32 | C36: 2026-09-01 | D36: Månadshyra server cykelkarta augusti | E36: -452
A37: Cykelkarta | B37: 33 | C37: 2026-09-09 | D37: Tryck cykelkarta Helsingborg syd | E37: -17914
A38: Cykelkarta | B38: 34 | C38: 2026-09-09 | D38: Tryck cykelkarta Helsingborg norr | E38: -17914
A39: Cykelkarta | B39: 40 | C39: 2026-10-02 | D39: Månadshyra server cykelkarta september | E39: -460
A40: Cykelkarta | D40: Månadshyra server cykelkarta oktober | F40: Rad utan belopp, datum och verifikationsnummer
A41: Fotoutställning | B41: 3 | C41: 2026-01-28 | D41: Polistillstånd fotoutställning | E41: -1980
...

Sheet Avstämning
A1: Avstämning: delsummor och slutrad
A2: Gult = värde avskrivet från huvudboken. Övriga celler är formler.
A4: Kategori | B4: Summa av rader (beräknad) | C4: Huvudbokens delsumma | D4: Skillnad
A5: Medlemsavgifter | B5: =SUMIF(Huvudbok!$A$5:$A$47,A5,Huvudbok!$E$5:$E$47) -> 66156 | C5: 66156 | D5: =ROUND(B5-C5,2) -> 0
A6: Miljöanslag | B6: =SUMIF(Huvudbok!$A$5:$A$47,A6,Huvudbok!$E$5:$E$47) -> 54000 | C6: 54000 | D6: =ROUND(B6-C6,2) -> 0
A7: Ersättning cykelkarta | B7: =SUMIF(Huvudbok!$A$5:$A$47,A7,Huvudbok!$E$5:$E$47) -> 97000 | C7: 97000 | D7: =ROUND(B7-C7,2) -> 0
A8: Administration | B8: =SUMIF(Huvudbok!$A$5:$A$47,A8,Huvudbok!$E$5:$E$47) -> -5915 | C8: -5915 | D8: =ROUND(B8-C8,2) -> 0
A9: Programblad | B9: =SUMIF(Huvudbok!$A$5:$A$47,A9,Huvudbok!$E$5:$E$47) -> -75500 | C9: -75500 | D9: =ROUND(B9-C9,2) -> 0
A10: Arrangemang | B10: =SUMIF(Huvudbok!$A$5:$A$47,A10,Huvudbok!$E$5:$E$47) -> -1208.85 | C10: -1208.85 | D10: =ROUND(B10-C10,2) -> 0
A11: Cykelkarta | B11: =SUMIF(Huvudbok!$A$5:$A$47,A11,Huvudbok!$E$5:$E$47) -> -92115.91 | C11: -92115.91 | D11: =ROUND(B11-C11,2) -> 0
A12: Fotoutställning | B12: =SUMIF(Huvudbok!$A$5:$A$47,A12,Huvudbok!$E$5:$E$47) -> -54024.56 | C12: -54024.56 | D12: =ROUND(B12-C12,2) -> 0
A13: Resultat (summa av delsummor) | B13: =SUM(B5:B12) -> -11608.32 | C13: =SUM(C5:C12) -> -11608.32 | D13: =ROUND(B13-C13,2) -> 0
A14: Huvudbokens slutrad ("Resultat") | C14: -11268.32
A15: Skillnad: beräknat resultat minus huvudbokens slutrad | B15: =ROUND(B13-C14,2) -> -340 | C15: ← 0 om slutraden stämmer

Sheet Scenario
A1: Scenario: vad ger huvudbokens slutrad om vissa rader inte räknats med?
A2: Ändra gula celler: 1 = raden är med i slutraden, 0 = inte med. Skriv ett negativt belopp för serverhyra oktober om du vill pröva det.
A4: Huvudbokens slutrad | B4: =Avstämning!C14 -> -11268.32
A5: Rader t.o.m. verifikat 37 (= förra periodens resultat) | B5: =ROUND(SUM(Huvudbok!E5:E47)-(Huvudbok!E23+Huvudbok!E14+Huvudbok!E39+Huvudbok!E15),2) -> -9356.32
A7: Post | B7: Belopp (kr) | C7: Med i slutraden (1/0)
A8: Verifikat 38 Frimärken | B8: =Huvudbok!E23 -> -242 | C8: 1
A9: Verifikat 39 Muggar | B9: =Huvudbok!E14 -> -100 | C9: 1
A10: Verifikat 40 Serverhyra september | B10: =Huvudbok!E39 -> -460 | C10: 1
A11: Hyra Kvisten Skrylle (utan verifikat) | B11: =Huvudbok!E15 -> -1450 | C11: 1
A12: Serverhyra oktober (belopp, negativt) | B12: 0
A14: Resultat enligt scenariot | B14: =ROUND(B5+SUMPRODUCT(B8:B11,C8:C11)+B12,2) -> -11608.32
A15: Skillnad mot huvudbokens slutrad | B15: =ROUND(B14-B4,2) -> -340 | C15: ← 0 betyder att scenariot förklarar slutraden
A17: Färdiga hypoteser
A18: Hypotes | B18: Resultat / belopp | C18: Skillnad mot slutrad
A19: H1: slutraden saknar verifikat 38 och 39 (resultat) | B19: =ROUND(Avstämning!B13-Huvudbok!E23-Huvudbok!E14,2) -> -11266.32 | C19: =ROUND(B19-B4,2) -> 2
A20: H2: slutraden saknar 38, 39 och 40 men har serverhyra oktober (belopp som krävs) | B20: =ROUND(B4-B5-Huvudbok!E15,2) -> -462
A21: H3: saknad post som krävs (intäkt +, kostnad −) | B21: =ROUND(B4-Avstämning!B13,2) -> 340
